Workbook

Sheet 1_참가선수입력
A1: 제27회 경희대학교 총장배 참가선수 입력표 (최대 210명)
A3: 번호 | B3: 접수일 | C3: 참가구분 | D3: 성별 | E3: 이름 | F3: 학교 | G3: 학년 | H3: 생년월일 | I3: 선수 연락처 | J3: 보호자 연락처 | K3: 이메일 | L3: 참가비 입금 | M3: 입금일 | N3: 학교폭력 서약서 | O3: 안전 서약서 | P3: 개인정보 동의서 | Q3: 신청서 | R3: 서류상태 | S3: 1일차 조 | T3: 1일차 부 | U3: 1일차 출발시간 | V3: 최종일 진출 | W3: 비고
A4: 1 | R4: =IF(AND(L4="완료",N4="완료",O4="완료",P4="완료",Q4="완료"),"완료","확인필요") -> 확인필요 | S4: =IF(E4<>"",ROUNDUP(A4/4,0),"") | T4: =IF(S4="","",IF(S4<=26,"1부","2부")) | U4: =IF(S4="","",INDEX('2_1일차조편성'!$E$4:$E$56,S4)) | V4: =IFERROR(IF(VLOOKUP(A4,'4_스코어입력'!$A$4:$K$213,11,FALSE)<=104,"진출",""),"")
A5: 2 | R5: =IF(AND(L5="완료",N5="완료",O5="완료",P5="완료",Q5="완료"),"완료","확인필요") -> 확인필요 | S5: =IF(E5<>"",ROUNDUP(A5/4,0),"") | T5: =IF(S5="","",IF(S5<=26,"1부","2부")) | U5: =IF(S5="","",INDEX('2_1일차조편성'!$E$4:$E$56,S5)) | V5: =IFERROR(IF(VLOOKUP(A5,'4_스코어입력'!$A$4:$K$213,11,FALSE)<=104,"진출",""),"")
A6: 3 | R6: =IF(AND(L6="완료",N6="완료",O6="완료",P6="완료",Q6="완료"),"완료","확인필요") -> 확인필요 | S6: =IF(E6<>"",ROUNDUP(A6/4,0),"") | T6: =IF(S6="","",IF(S6<=26,"1부","2부")) | U6: =IF(S6="","",INDEX('2_1일차조편성'!$E$4:$E$56,S6)) | V6: =IFERROR(IF(VLOOKUP(A6,'4_스코어입력'!$A$4:$K$213,11,FALSE)<=104,"진출",""),"")
A7: 4 | R7: =IF(AND(L7="완료",N7="완료",O7="완료",P7="완료",Q7="완료"),"완료","확인필요") -> 확인필요 | S7: =IF(E7<>"",ROUNDUP(A7/4,0),"") | T7: =IF(S7="","",IF(S7<=26,"1부","2부")) | U7: =IF(S7="","",INDEX('2_1일차조편성'!$E$4:$E$56,S7)) | V7: =IFERROR(IF(VLOOKUP(A7,'4_스코어입력'!$A$4:$K$213,11,FALSE)<=104,"진출",""),"")
A8: 5 | R8: =IF(AND(L8="완료",N8="완료",O8="완료",P8="완료",Q8="완료"),"완료","확인필요") -> 확인필요 | S8: =IF(E8<>"",ROUNDUP(A8/4,0),"") | T8: =IF(S8="","",IF(S8<=26,"1부","2부")) | U8: =IF(S8="","",INDEX('2_1일차조편성'!$E$4:$E$56,S8)) | V8: =IFERROR(IF(VLOOKUP(A8,'4_스코어입력'!$A$4:$K$213,11,FALSE)<=104,"진출",""),"")
A9: 6 | R9: =IF(AND(L9="완료",N9="완료",O9="완료",P9="완료",Q9="완료"),"완료","확인필요") -> 확인필요 | S9: =IF(E9<>"",ROUNDUP(A9/4,0),"") | T9: =IF(S9="","",IF(S9<=26,"1부","2부")) | U9: =IF(S9="","",INDEX('2_1일차조편성'!$E$4:$E$56,S9)) | V9: =IFERROR(IF(VLOOKUP(A9,'4_스코어입력'!$A$4:$K$213,11,FALSE)<=104,"진출",""),"")
A10: 7 | R10: =IF(AND(L10="완료",N10="완료",O10="완료",P10="완료",Q10="완료"),"완료","확인필요") -> 확인필요 | S10: =IF(E10<>"",ROUNDUP(A10/4,0),"") | T10: =IF(S10="","",IF(S10<=26,"1부","2부")) | U10: =IF(S10="","",INDEX('2_1일차조편성'!$E$4:$E$56,S10)) | V10: =IFERROR(IF(VLOOKUP(A10,'4_스코어입력'!$A$4:$K$213,11,FALSE)<=104,"진출",""),"")
A11: 8 | R11: =IF(AND(L11="완료",N11="완료",O11="완료",P11="완료",Q11="완료"),"완료","확인필요") -> 확인필요 | S11: =IF(E11<>"",ROUNDUP(A11/4,0),"") | T11: =IF(S11="","",IF(S11<=26,"1부","2부")) | U11: =IF(S11="","",INDEX('2_1일차조편성'!$E$4:$E$56,S11)) | V11: =IFERROR(IF(VLOOKUP(A11,'4_스코어입력'!$A$4:$K$213,11,FALSE)<=104,"진출",""),"")
A12: 9 | R12: =IF(AND(L12="완료",N12="완료",O12="완료",P12="완료",Q12="완료"),"완료","확인필요") -> 확인필요 | S12: =IF(E12<>"",ROUNDUP(A12/4,0),"") | T12: =IF(S12="","",IF(S12<=26,"1부","2부")) | U12: =IF(S12="","",INDEX('2_1일차조편성'!$E$4:$E$56,S12)) | V12: =IFERROR(IF(VLOOKUP(A12,'4_스코어입력'!$A$4:$K$213,11,FALSE)<=104,"진출",""),"")
A13: 10 | R13: =IF(AND(L13="완료",N13="완료",O13="완료",P13="완료",Q13="완료"),"완료","확인필요") -> 확인필요 | S13: =IF(E13<>"",ROUNDUP(A13/4,0),"") | T13: =IF(S13="","",IF(S13<=26,"1부","2부")) | U13: =IF(S13="","",INDEX('2_1일차조편성'!$E$4:$E$56,S13)) | V13: =IFERROR(IF(VLOOKUP(A13,'4_스코어입력'!$A$4:$K$213,11,FALSE)<=104,"진출",""),"")
A14: 11 | R14: =IF(AND(L14="완료",N14="완료",O14="완료",P14="완료",Q14="완료"),"완료","확인필요") -> 확인필요 | S14: =IF(E14<>"",ROUNDUP(A14/4,0),"") | T14: =IF(S14="","",IF(S14<=26,"1부","2부")) | U14: =IF(S14="","",INDEX('2_1일차조편성'!$E$4:$E$56,S14)) | V14: =IFERROR(IF(VLOOKUP(A14,'4_스코어입력'!$A$4:$K$213,11,FALSE)<=104,"진출",""),"")
A15: 12 | R15: =IF(AND(L15="완료",N15="완료",O15="완료",P15="완료",Q15="완료"),"완료","확인필요") -> 확인필요 | S15: =IF(E15<>"",ROUNDUP(A15/4,0),"") | T15: =IF(S15="","",IF(S15<=26,"1부","2부")) | U15: =IF(S15="","",INDEX('2_1일차조편성'!$E$4:$E$56,S15)) | V15: =IFERROR(IF(VLOOKUP(A15,'4_스코어입력'!$A$4:$K$213,11,FALSE)<=104,"진출",""),"")
... A213: 210 | R213: =IF(AND(L213="완료",N213="완료",O213="완료",P213="완료",Q213="완료"),"완료","확인필요") -> 확인필요 | S213: =IF(E213<>"",ROUNDUP(A213/4,0),"") | T213: =IF(S213="","",IF(S213<=26,"1부","2부")) | U213: =IF(S213="","",INDEX('2_1일차조편성'!$E$4:$E$56,S213)) | V213: =IFERROR(IF(VLOOKUP(A213,'4_스코어입력'!$A$4:$K$213,11,FALSE)<=104,"진출",""),"")

Sheet 2_1일차조편성
A1: 1일차 자동 조편성표 (입력 순서 기준 / 4인 1조)
N2: 1부 시작 | O2: 07:00
A3: 조 | B3: 일자 | C3: 라운드 | D3: 부 | E3: 출발시간 | F3: 선수1 | G3: 선수2 | H3: 선수3 | I3: 선수4 | J3: 구분/성별 확인 | K3: 카트/캐디 | L3: 비고 | N3: 2부 시작 | O3: 11:30
A4: 1 | B4: 6/24(수) | C4: 제1라운드 | D4: =IF(A4<=26,"1부","2부") -> 1부 | E4: =IF(A4<=26,$O$2+(A4-1)*TIME(0,$O$4,0),$O$3+(A4-27)*TIME(0,$O$4,0)) -> 0.29166667 | F4: =IF('1_참가선수입력'!$E$4<>"",'1_참가선수입력'!$E$4,"") | G4: =IF('1_참가선수입력'!$E$5<>"",'1_참가선수입력'!$E$5,"") | H4: =IF('1_참가선수입력'!$E$6<>"",'1_참가선수입력'!$E$6,"") | I4: =IF('1_참가선수입력'!$E$7<>"",'1_참가선수입력'!$E$7,"") | J4: =TEXTJOIN(" / ",TRUE,'1_참가선수입력'!C4:D7) -> #NAME? | N4: 간격(분) | O4: 8
A5: 2 | B5: 6/24(수) | C5: 제1라운드 | D5: =IF(A5<=26,"1부","2부") -> 1부 | E5: =IF(A5<=26,$O$2+(A5-1)*TIME(0,$O$4,0),$O$3+(A5-27)*TIME(0,$O$4,0)) -> 0.29722222 | F5: =IF('1_참가선수입력'!$E$8<>"",'1_참가선수입력'!$E$8,"") | G5: =IF('1_참가선수입력'!$E$9<>"",'1_참가선수입력'!$E$9,"") | H5: =IF('1_참가선수입력'!$E$10<>"",'1_참가선수입력'!$E$10,"") | I5: =IF('1_참가선수입력'!$E$11<>"",'1_참가선수입력'!$E$11,"") | J5: =TEXTJOIN(" / ",TRUE,'1_참가선수입력'!C8:D11) -> #NAME?
A6: 3 | B6: 6/24(수) | C6: 제1라운드 | D6: =IF(A6<=26,"1부","2부") -> 1부 | E6: =IF(A6<=26,$O$2+(A6-1)*TIME(0,$O$4,0),$O$3+(A6-27)*TIME(0,$O$4,0)) -> 0.30277778 | F6: =IF('1_참가선수입력'!$E$12<>"",'1_참가선수입력'!$E$12,"") | G6: =IF('1_참가선수입력'!$E$13<>"",'1_참가선수입력'!$E$13,"") | H6: =IF('1_참가선수입력'!$E$14<>"",'1_참가선수입력'!$E$14,"") | I6: =IF('1_참가선수입력'!$E$15<>"",'1_참가선수입력'!$E$15,"") | J6: =TEXTJOIN(" / ",TRUE,'1_참가선수입력'!C12:D15) -> #NAME?
A7: 4 | B7: 6/24(수) | C7: 제1라운드 | D7: =IF(A7<=26,"1부","2부") -> 1부 | E7: =IF(A7<=26,$O$2+(A7-1)*TIME(0,$O$4,0),$O$3+(A7-27)*TIME(0,$O$4,0)) -> 0.30833333 | F7: =IF('1_참가선수입력'!$E$16<>"",'1_참가선수입력'!$E$16,"") | G7: =IF('1_참가선수입력'!$E$17<>"",'1_참가선수입력'!$E$17,"") | H7: =IF('1_참가선수입력'!$E$18<>"",'1_참가선수입력'!$E$18,"") | I7: =IF('1_참가선수입력'!$E$19<>"",'1_참가선수입력'!$E$19,"") | J7: =TEXTJOIN(" / ",TRUE,'1_참가선수입력'!C16:D19) -> #NAME?
A8: 5 | B8: 6/24(수) | C8: 제1라운드 | D8: =IF(A8<=26,"1부","2부") -> 1부 | E8: =IF(A8<=26,$O$2+(A8-1)*TIME(0,$O$4,0),$O$3+(A8-27)*TIME(0,$O$4,0)) -> 0.31388889 | F8: =IF('1_참가선수입력'!$E$20<>"",'1_참가선수입력'!$E$20,"") | G8: =IF('1_참가선수입력'!$E$21<>"",'1_참가선수입력'!$E$21,"") | H8: =IF('1_참가선수입력'!$E$22<>"",'1_참가선수입력'!$E$22,"") | I8: =IF('1_참가선수입력'!$E$23<>"",'1_참가선수입력'!$E$23,"") | J8: =TEXTJOIN(" / ",TRUE,'1_참가선수입력'!C20:D23) -> #NAME?
A9: 6 | B9: 6/24(수) | C9: 제1라운드 | D9: =IF(A9<=26,"1부","2부") -> 1부 | E9: =IF(A9<=26,$O$2+(A9-1)*TIME(0,$O$4,0),$O$3+(A9-27)*TIME(0,$O$4,0)) -> 0.31944444 | F9: =IF('1_참가선수입력'!$E$24<>"",'1_참가선수입력'!$E$24,"") | G9: =IF('1_참가선수입력'!$E$25<>"",'1_참가선수입력'!$E$25,"") | H9: =IF('1_참가선수입력'!$E$26<>"",'1_참가선수입력'!$E$26,"") | I9: =IF('1_참가선수입력'!$E$27<>"",'1_참가선수입력'!$E$27,"") | J9: =TEXTJOIN(" / ",TRUE,'1_참가선수입력'!C24:D27) -> #NAME?
A10: 7 | B10: 6/24(수) | C10: 제1라운드 | D10: =IF(A10<=26,"1부","2부") -> 1부 | E10: =IF(A10<=26,$O$2+(A10-1)*TIME(0,$O$4,0),$O$3+(A10-27)*TIME(0,$O$4,0)) -> 0.325 | F10: =IF('1_참가선수입력'!$E$28<>"",'1_참가선수입력'!$E$28,"") | G10: =IF('1_참가선수입력'!$E$29<>"",'1_참가선수입력'!$E$29,"") | H10: =IF('1_참가선수입력'!$E$30<>"",'1_참가선수입력'!$E$30,"") | I10: =IF('1_참가선수입력'!$E$31<>"",'1_참가선수입력'!$E$31,"") | J10: =TEXTJOIN(" / ",TRUE,'1_참가선수입력'!C28:D31) -> #NAME?
A11: 8 | B11: 6/24(수) | C11: 제1라운드 | D11: =IF(A11<=26,"1부","2부") -> 1부 | E11: =IF(A11<=26,$O$2+(A11-1)*TIME(0,$O$4,0),$O$3+(A11-27)*TIME(0,$O$4,0)) -> 0.33055556 | F11: =IF('1_참가선수입력'!$E$32<>"",'1_참가선수입력'!$E$32,"") | G11: =IF('1_참가선수입력'!$E$33<>"",'1_참가선수입력'!$E$33,"") | H11: =IF('1_참가선수입력'!$E$34<>"",'1_참가선수입력'!$E$34,"") | I11: =IF('1_참가선수입력'!$E$35<>"",'1_참가선수입력'!$E$35,"") | J11: =TEXTJOIN(" / ",TRUE,'1_참가선수입력'!C32:D35) -> #NAME?
A12: 9 | B12: 6/24(수) | C12: 제1라운드 | D12: =IF(A12<=26,"1부","2부") -> 1부 | E12: =IF(A12<=26,$O$2+(A12-1)*TIME(0,$O$4,0),$O$3+(A12-27)*TIME(0,$O$4,0)) -> 0.33611111 | F12: =IF('1_참가선수입력'!$E$36<>"",'1_참가선수입력'!$E$36,"") | G12: =IF('1_참가선수입력'!$E$37<>"",'1_참가선수입력'!$E$37,"") | H12: =IF('1_참가선수입력'!$E$38<>"",'1_참가선수입력'!$E$38,"") | I12: =IF('1_참가선수입력'!$E$39<>"",'1_참가선수입력'!$E$39,"") | J12: =TEXTJOIN(" / ",TRUE,'1_참가선수입력'!C36:D39) -> #NAME?
A13: 10 | B13: 6/24(수) | C13: 제1라운드 | D13: =IF(A13<=26,"1부","2부") -> 1부 | E13: =IF(A13<=26,$O$2+(A13-1)*TIME(0,$O$4,0),$O$3+(A13-27)*TIME(0,$O$4,0)) -> 0.34166667 | F13: =IF('1_참가선수입력'!$E$40<>"",'1_참가선수입력'!$E$40,"") | G13: =IF('1_참가선수입력'!$E$41<>"",'1_참가선수입력'!$E$41,"") | H13: =IF('1_참가선수입력'!$E$42<>"",'1_참가선수입력'!$E$42,"") | I13: =IF('1_참가선수입력'!$E$43<>"",'1_참가선수입력'!$E$43,"") | J13: =TEXTJOIN(" / ",TRUE,'1_참가선수입력'!C40:D43) -> #NAME?
A14: 11 | B14: 6/24(수) | C14: 제1라운드 | D14: =IF(A14<=26,"1부","2부") -> 1부 | E14: =IF(A14<=26,$O$2+(A14-1)*TIME(0,$O$4,0),$O$3+(A14-27)*TIME(0,$O$4,0)) -> 0.34722222 | F14: =IF('1_참가선수입력'!$E$44<>"",'1_참가선수입력'!$E$44,"") | G14: =IF('1_참가선수입력'!$E$45<>"",'1_참가선수입력'!$E$45,"") | H14: =IF('1_참가선수입력'!$E$46<>"",'1_참가선수입력'!$E$46,"") | I14: =IF('1_참가선수입력'!$E$47<>"",'1_참가선수입력'!$E$47,"") | J14: =TEXTJOIN(" / ",TRUE,'1_참가선수입력'!C44:D47) -> #NAME?
A15: 12 | B15: 6/24(수) | C15: 제1라운드 | D15: =IF(A15<=26,"1부","2부") -> 1부 | E15: =IF(A15<=26,$O$2+(A15-1)*TIME(0,$O$4,0),$O$3+(A15-27)*TIME(0,$O$4,0)) -> 0.35277778 | F15: =IF('1_참가선수입력'!$E$48<>"",'1_참가선수입력'!$E$48,"") | G15: =IF('1_참가선수입력'!$E$49<>"",'1_참가선수입력'!$E$49,"") | H15: =IF('1_참가선수입력'!$E$50<>"",'1_참가선수입력'!$E$50,"") | I15: =IF('1_참가선수입력'!$E$51<>"",'1_참가선수입력'!$E$51,"") | J15: =TEXTJOIN(" / ",TRUE,'1_참가선수입력'!C48:D51) -> #NAME?
A16: 13 | B16: 6/24(수) | C16: 제1라운드 | D16: =IF(A16<=26,"1부","2부") -> 1부 | E16: =IF(A16<=26,$O$2+(A16-1)*TIME(0,$O$4,0),$O$3+(A16-27)*TIME(0,$O$4,0)) -> 0.35833333 | F16: =IF('1_참가선수입력'!$E$52<>"",'1_참가선수입력'!$E$52,"") | G16: =IF('1_참가선수입력'!$E$53<>"",'1_참가선수입력'!$E$53,"") | H16: =IF('1_참가선수입력'!$E$54<>"",'1_참가선수입력'!$E$54,"") | I16: =IF('1_참가선수입력'!$E$55<>"",'1_참가선수입력'!$E$55,"") | J16: =TEXTJOIN(" / ",TRUE,'1_참가선수입력'!C52:D55) -> #NAME?
A17: 14 | B17: 6/24(수) | C17: 제1라운드 | D17: =IF(A17<=26,"1부","2부") -> 1부 | E17: =IF(A17<=26,$O$2+(A17-1)*TIME(0,$O$4,0),$O$3+(A17-27)*TIME(0,$O$4,0)) -> 0.36388889 | F17: =IF('1_참가선수입력'!$E$56<>"",'1_참가선수입력'!$E$56,"") | G17: =IF('1_참가선수입력'!$E$57<>"",'1_참가선수입력'!$E$57,"") | H17: =IF('1_참가선수입력'!$E$58<>"",'1_참가선수입력'!$E$58,"") | I17: =IF('1_참가선수입력'!$E$59<>"",'1_참가선수입력'!$E$59,"") | J17: =TEXTJOIN(" / ",TRUE,'1_참가선수입력'!C56:D59) -> #NAME?
A18: 15 | B18: 6/24(수) | C18: 제1라운드 | D18: =IF(A18<=26,"1부","2부") -> 1부 | E18: =IF(A18<=26,$O$2+(A18-1)*TIME(0,$O$4,0),$O$3+(A18-27)*TIME(0,$O$4,0)) -> 0.36944444 | F18: =IF('1_참가선수입력'!$E$60<>"",'1_참가선수입력'!$E$60,"") | G18: =IF('1_참가선수입력'!$E$61<>"",'1_참가선수입력'!$E$61,"") | H18: =IF('1_참가선수입력'!$E$62<>"",'1_참가선수입력'!$E$62,"") | I18: =IF('1_참가선수입력'!$E$63<>"",'1_참가선수입력'!$E$63,"") | J18: =TEXTJOIN(" / ",TRUE,'1_참가선수입력'!C60:D63) -> #NAME?
A19: 16 | B19: 6/24(수) | C19: 제1라운드 | D19: =IF(A19<=26,"1부","2부") -> 1부 | E19: =IF(A19<=26,$O$2+(A19-1)*TIME(0,$O$4,0),$O$3+(A19-27)*TIME(0,$O$4,0)) -> 0.375 | F19: =IF('1_참가선수입력'!$E$64<>"",'1_참가선수입력'!$E$64,"") | G19: =IF('1_참가선수입력'!$E$65<>"",'1_참가선수입력'!$E$65,"") | H19: =IF('1_참가선수입력'!$E$66<>"",'1_참가선수입력'!$E$66,"") | I19: =IF('1_참가선수입력'!$E$67<>"",'1_참가선수입력'!$E$67,"") | J19: =TEXTJOIN(" / ",TRUE,'1_참가선수입력'!C64:D67) -> #NAME?
A20: 17 | B20: 6/24(수) | C20: 제1라운드 | D20: =IF(A20<=26,"1부","2부") -> 1부 | E20: =IF(A20<=26,$O$2+(A20-1)*TIME(0,$O$4,0),$O$3+(A20-27)*TIME(0,$O$4,0)) -> 0.38055556 | F20: =IF('1_참가선수입력'!$E$68<>"",'1_참가선수입력'!$E$68,"") | G20: =IF('1_참가선수입력'!$E$69<>"",'1_참가선수입력'!$E$69,"") | H20: =IF('1_참가선수입력'!$E$70<>"",'1_참가선수입력'!$E$70,"") | I20: =IF('1_참가선수입력'!$E$71<>"",'1_참가선수입력'!$E$71,"") | J20: =TEXTJOIN(" / ",TRUE,'1_참가선수입력'!C68:D71) -> #NAME?
A21: 18 | B21: 6/24(수) | C21: 제1라운드 | D21: =IF(A21<=26,"1부","2부") -> 1부 | E21: =IF(A21<=26,$O$2+(A21-1)*TIME(0,$O$4,0),$O$3+(A21-27)*TIME(0,$O$4,0)) -> 0.38611111 | F21: =IF('1_참가선수입력'!$E$72<>"",'1_참가선수입력'!$E$72,"") | G21: =IF('1_참가선수입력'!$E$73<>"",'1_참가선수입력'!$E$73,"") | H21: =IF('1_참가선수입력'!$E$74<>"",'1_참가선수입력'!$E$74,"") | I21: =IF('1_참가선수입력'!$E$75<>"",'1_참가선수입력'!$E$75,"") | J21: =TEXTJOIN(" / ",TRUE,'1_참가선수입력'!C72:D75) -> #NAME?
A22: 19 | B22: 6/24(수) | C22: 제1라운드 | D22: =IF(A22<=26,"1부","2부") -> 1부 | E22: =IF(A22<=26,$O$2+(A22-1)*TIME(0,$O$4,0),$O$3+(A22-27)*TIME(0,$O$4,0)) -> 0.39166667 | F22: =IF('1_참가선수입력'!$E$76<>"",'1_참가선수입력'!$E$76,"") | G22: =IF('1_참가선수입력'!$E$77<>"",'1_참가선수입력'!$E$77,"") | H22: =IF('1_참가선수입력'!$E$78<>"",'1_참가선수입력'!$E$78,"") | I22: =IF('1_참가선수입력'!$E$79<>"",'1_참가선수입력'!$E$79,"") | J22: =TEXTJOIN(" / ",TRUE,'1_참가선수입력'!C76:D79) -> #NAME?
A23: 20 | B23: 6/24(수) | C23: 제1라운드 | D23: =IF(A23<=26,"1부","2부") -> 1부 | E23: =IF(A23<=26,$O$2+(A23-1)*TIME(0,$O$4,0),$O$3+(A23-27)*TIME(0,$O$4,0)) -> 0.39722222 | F23: =IF('1_참가선수입력'!$E$80<>"",'1_참가선수입력'!$E$80,"") | G23: =IF('1_참가선수입력'!$E$81<>"",'1_참가선수입력'!$E$81,"") | H23: =IF('1_참가선수입력'!$E$82<>"",'1_참가선수입력'!$E$82,"") | I23: =IF('1_참가선수입력'!$E$83<>"",'1_참가선수입력'!$E$83,"") | J23: =TEXTJOIN(" / ",TRUE,'1_참가선수입력'!C80:D83) -> #NAME?
A24: 21 | B24: 6/24(수) | C24: 제1라운드 | D24: =IF(A24<=26,"1부","2부") -> 1부 | E24: =IF(A24<=26,$O$2+(A24-1)*TIME(0,$O$4,0),$O$3+(A24-27)*TIME(0,$O$4,0)) -> 0.40277778 | F24: =IF('1_참가선수입력'!$E$84<>"",'1_참가선수입력'!$E$84,"") | G24: =IF('1_참가선수입력'!$E$85<>"",'1_참가선수입력'!$E$85,"") | H24: =IF('1_참가선수입력'!$E$86<>"",'1_참가선수입력'!$E$86,"") | I24: =IF('1_참가선수입력'!$E$87<>"",'1_참가선수입력'!$E$87,"") | J24: =TEXTJOIN(" / ",TRUE,'1_참가선수입력'!C84:D87) -> #NAME?
A25: 22 | B25: 6/24(수) | C25: 제1라운드 | D25: =IF(A25<=26,"1부","2부") -> 1부 | E25: =IF(A25<=26,$O$2+(A25-1)*TIME(0,$O$4,0),$O$3+(A25-27)*TIME(0,$O$4,0)) -> 0.40833333 | F25: =IF('1_참가선수입력'!$E$88<>"",'1_참가선수입력'!$E$88,"") | G25: =IF('1_참가선수입력'!$E$89<>"",'1_참가선수입력'!$E$89,"") | H25: =IF('1_참가선수입력'!$E$90<>"",'1_참가선수입력'!$E$90,"") | I25: =IF('1_참가선수입력'!$E$91<>"",'1_참가선수입력'!$E$91,"") | J25: =TEXTJOIN(" / ",TRUE,'1_참가선수입력'!C88:D91) -> #NAME?
A26: 23 | B26: 6/24(수) | C26: 제1라운드 | D26: =IF(A26<=26,"1부","2부") -> 1부 | E26: =IF(A26<=26,$O$2+(A26-1)*TIME(0,$O$4,0),$O$3+(A26-27)*TIME(0,$O$4,0)) -> 0.41388889 | F26: =IF('1_참가선수입력'!$E$92<>"",'1_참가선수입력'!$E$92,"") | G26: =IF('1_참가선수입력'!$E$93<>"",'1_참가선수입력'!$E$93,"") | H26: =IF('1_참가선수입력'!$E$94<>"",'1_참가선수입력'!$E$94,"") | I26: =IF('1_참가선수입력'!$E$95<>"",'1_참가선수입력'!$E$95,"") | J26: =TEXTJOIN(" / ",TRUE,'1_참가선수입력'!C92:D95) -> #NAME?
A27: 24 | B27: 6/24(수) | C27: 제1라운드 | D27: =IF(A27<=26,"1부","2부") -> 1부 | E27: =IF(A27<=26,$O$2+(A27-1)*TIME(0,$O$4,0),$O$3+(A27-27)*TIME(0,$O$4,0)) -> 0.41944444 | F27: =IF('1_참가선수입력'!$E$96<>"",'1_참가선수입력'!$E$96,"") | G27: =IF('1_참가선수입력'!$E$97<>"",'1_참가선수입력'!$E$97,"") | H27: =IF('1_참가선수입력'!$E$98<>"",'1_참가선수입력'!$E$98,"") | I27: =IF('1_참가선수입력'!$E$99<>"",'1_참가선수입력'!$E$99,"") | J27: =TEXTJOIN(" / ",TRUE,'1_참가선수입력'!C96:D99) -> #NAME?
A28: 25 | B28: 6/24(수) | C28: 제1라운드 | D28: =IF(A28<=26,"1부","2부") -> 1부 | E28: =IF(A28<=26,$O$2+(A28-1)*TIME(0,$O$4,0),$O$3+(A28-27)*TIME(0,$O$4,0)) -> 0.425 | F28: =IF('1_참가선수입력'!$E$100<>"",'1_참가선수입력'!$E$100,"") | G28: =IF('1_참가선수입력'!$E$101<>"",'1_참가선수입력'!$E$101,"") | H28: =IF('1_참가선수입력'!$E$102<>"",'1_참가선수입력'!$E$102,"") | I28: =IF('1_참가선수입력'!$E$103<>"",'1_참가선수입력'!$E$103,"") | J28: =TEXTJOIN(" / ",TRUE,'1_참가선수입력'!C100:D103) -> #NAME?
A29: 26 | B29: 6/24(수) | C29: 제1라운드 | D29: =IF(A29<=26,"1부","2부") -> 1부 | E29: =IF(A29<=26,$O$2+(A29-1)*TIME(0,$O$4,0),$O$3+(A29-27)*TIME(0,$O$4,0)) -> 0.43055556 | F29: =IF('1_참가선수입력'!$E$104<>"",'1_참가선수입력'!$E$104,"") | G29: =IF('1_참가선수입력'!$E$105<>"",'1_참가선수입력'!$E$105,"") | H29: =IF('1_참가선수입력'!$E$106<>"",'1_참가선수입력'!$E$106,"") | I29: =IF('1_참가선수입력'!$E$107<>"",'1_참가선수입력'!$E$107,"") | J29: =TEXTJOIN(" / ",TRUE,'1_참가선수입력'!C104:D107) -> #NAME?
A30: 27 | B30: 6/24(수) | C30: 제1라운드 | D30: =IF(A30<=26,"1부","2부") -> 2부 | E30: =IF(A30<=26,$O$2+(A30-1)*TIME(0,$O$4,0),$O$3+(A30-27)*TIME(0,$O$4,0)) -> 0.47916667 | F30: =IF('1_참가선수입력'!$E$108<>"",'1_참가선수입력'!$E$108,"") | G30: =IF('1_참가선수입력'!$E$109<>"",'1_참가선수입력'!$E$109,"") | H30: =IF('1_참가선수입력'!$E$110<>"",'1_참가선수입력'!$E$110,"") | I30: =IF('1_참가선수입력'!$E$111<>"",'1_참가선수입력'!$E$111,"") | J30: =TEXTJOIN(" / ",TRUE,'1_참가선수입력'!C108:D111) -> #NAME?
A31: 28 | B31: 6/24(수) | C31: 제1라운드 | D31: =IF(A31<=26,"1부","2부") -> 2부 | E31: =IF(A31<=26,$O$2+(A31-1)*TIME(0,$O$4,0),$O$3+(A31-27)*TIME(0,$O$4,0)) -> 0.48472222 | F31: =IF('1_참가선수입력'!$E$112<>"",'1_참가선수입력'!$E$112,"") | G31: =IF('1_참가선수입력'!$E$113<>"",'1_참가선수입력'!$E$113,"") | H31: =IF('1_참가선수입력'!$E$114<>"",'1_참가선수입력'!$E$114,"") | I31: =IF('1_참가선수입력'!$E$115<>"",'1_참가선수입력'!$E$115,"") | J31: =TEXTJOIN(" / ",TRUE,'1_참가선수입력'!C112:D115) -> #NAME?
A32: 29 | B32: 6/24(수) | C32: 제1라운드 | D32: =IF(A32<=26,"1부","2부") -> 2부 | E32: =IF(A32<=26,$O$2+(A32-1)*TIME(0,$O$4,0),$O$3+(A32-27)*TIME(0,$O$4,0)) -> 0.49027778 | F32: =IF('1_참가선수입력'!$E$116<>"",'1_참가선수입력'!$E$116,"") | G32: =IF('1_참가선수입력'!$E$117<>"",'1_참가선수입력'!$E$117,"") | H32: =IF('1_참가선수입력'!$E$118<>"",'1_참가선수입력'!$E$118,"") | I32: =IF('1_참가선수입력'!$E$119<>"",'1_참가선수입력'!$E$119,"") | J32: =TEXTJOIN(" / ",TRUE,'1_참가선수입력'!C116:D119) -> #NAME?
A33: 30 | B33: 6/24(수) | C33: 제1라운드 | D33: =IF(A33<=26,"1부","2부") -> 2부 | E33: =IF(A33<=26,$O$2+(A33-1)*TIME(0,$O$4,0),$O$3+(A33-27)*TIME(0,$O$4,0)) -> 0.49583333 | F33: =IF('1_참가선수입력'!$E$120<>"",'1_참가선수입력'!$E$120,"") | G33: =IF('1_참가선수입력'!$E$121<>"",'1_참가선수입력'!$E$121,"") | H33: =IF('1_참가선수입력'!$E$122<>"",'1_참가선수입력'!$E$122,"") | I33: =IF('1_참가선수입력'!$E$123<>"",'1_참가선수입력'!$E$123,"") | J33: =TEXTJOIN(" / ",TRUE,'1_참가선수입력'!C120:D123) -> #NAME?
A34: 31 | B34: 6/24(수) | C34: 제1라운드 | D34: =IF(A34<=26,"1부","2부") -> 2부 | E34: =IF(A34<=26,$O$2+(A34-1)*TIME(0,$O$4,0),$O$3+(A34-27)*TIME(0,$O$4,0)) -> 0.50138889 | F34: =IF('1_참가선수입력'!$E$124<>"",'1_참가선수입력'!$E$124,"") | G34: =IF('1_참가선수입력'!$E$125<>"",'1_참가선수입력'!$E$125,"") | H34: =IF('1_참가선수입력'!$E$126<>"",'1_참가선수입력'!$E$126,"") | I34: =IF('1_참가선수입력'!$E$127<>"",'1_참가선수입력'!$E$127,"") | J34: =TEXTJOIN(" / ",TRUE,'1_참가선수입력'!C124:D127) -> #NAME?
A35: 32 | B35: 6/24(수) | C35: 제1라운드 | D35: =IF(A35<=26,"1부","2부") -> 2부 | E35: =IF(A35<=26,$O$2+(A35-1)*TIME(0,$O$4,0),$O$3+(A35-27)*TIME(0,$O$4,0)) -> 0.50694444 | F35: =IF('1_참가선수입력'!$E$128<>"",'1_참가선수입력'!$E$128,"") | G35: =IF('1_참가선수입력'!$E$129<>"",'1_참가선수입력'!$E$129,"") | H35: =IF('1_참가선수입력'!$E$130<>"",'1_참가선수입력'!$E$130,"") | I35: =IF('1_참가선수입력'!$E$131<>"",'1_참가선수입력'!$E$131,"") | J35: =TEXTJOIN(" / ",TRUE,'1_참가선수입력'!C128:D131) -> #NAME?
A36: 33 | B36: 6/24(수) | C36: 제1라운드 | D36: =IF(A36<=26,"1부","2부") -> 2부 | E36: =IF(A36<=26,$O$2+(A36-1)*TIME(0,$O$4,0),$O$3+(A36-27)*TIME(0,$O$4,0)) -> 0.5125 | F36: =IF('1_참가선수입력'!$E$132<>"",'1_참가선수입력'!$E$132,"") | G36: =IF('1_참가선수입력'!$E$133<>"",'1_참가선수입력'!$E$133,"") | H36: =IF('1_참가선수입력'!$E$134<>"",'1_참가선수입력'!$E$134,"") | I36: =IF('1_참가선수입력'!$E$135<>"",'1_참가선수입력'!$E$135,"") | J36: =TEXTJOIN(" / ",TRUE,'1_참가선수입력'!C132:D135) -> #NAME?
A37: 34 | B37: 6/24(수) | C37: 제1라운드 | D37: =IF(A37<=26,"1부","2부") -> 2부 | E37: =IF(A37<=26,$O$2+(A37-1)*TIME(0,$O$4,0),$O$3+(A37-27)*TIME(0,$O$4,0)) -> 0.51805556 | F37: =IF('1_참가선수입력'!$E$136<>"",'1_참가선수입력'!$E$136,"") | G37: =IF('1_참가선수입력'!$E$137<>"",'1_참가선수입력'!$E$137,"") | H37: =IF('1_참가선수입력'!$E$138<>"",'1_참가선수입력'!$E$138,"") | I37: =IF('1_참가선수입력'!$E$139<>"",'1_참가선수입력'!$E$139,"") | J37: =TEXTJOIN(" / ",TRUE,'1_참가선수입력'!C136:D139) -> #NAME?
A38: 35 | B38: 6/24(수) | C38: 제1라운드 | D38: =IF(A38<=26,"1부","2부") -> 2부 | E38: =IF(A38<=26,$O$2+(A38-1)*TIME(0,$O$4,0),$O$3+(A38-27)*TIME(0,$O$4,0)) -> 0.52361111 | F38: =IF('1_참가선수입력'!$E$140<>"",'1_참가선수입력'!$E$140,"") | G38: =IF('1_참가선수입력'!$E$141<>"",'1_참가선수입력'!$E$141,"") | H38: =IF('1_참가선수입력'!$E$142<>"",'1_참가선수입력'!$E$142,"") | I38: =IF('1_참가선수입력'!$E$143<>"",'1_참가선수입력'!$E$143,"") | J38: =TEXTJOIN(" / ",TRUE,'1_참가선수입력'!C140:D143) -> #NAME?
A39: 36 | B39: 6/24(수) | C39: 제1라운드 | D39: =IF(A39<=26,"1부","2부") -> 2부 | E39: =IF(A39<=26,$O$2+(A39-1)*TIME(0,$O$4,0),$O$3+(A39-27)*TIME(0,$O$4,0)) -> 0.52916667 | F39: =IF('1_참가선수입력'!$E$144<>"",'1_참가선수입력'!$E$144,"") | G39: =IF('1_참가선수입력'!$E$145<>"",'1_참가선수입력'!$E$145,"") | H39: =IF('1_참가선수입력'!$E$146<>"",'1_참가선수입력'!$E$146,"") | I39: =IF('1_참가선수입력'!$E$147<>"",'1_참가선수입력'!$E$147,"") | J39: =TEXTJOIN(" / ",TRUE,'1_참가선수입력'!C144:D147) -> #NAME?
A40: 37 | B40: 6/24(수) | C40: 제1라운드 | D40: =IF(A40<=26,"1부","2부") -> 2부 | E40: =IF(A40<=26,$O$2+(A40-1)*TIME(0,$O$4,0),$O$3+(A40-27)*TIME(0,$O$4,0)) -> 0.53472222 | F40: =IF('1_참가선수입력'!$E$148<>"",'1_참가선수입력'!$E$148,"") | G40: =IF('1_참가선수입력'!$E$149<>"",'1_참가선수입력'!$E$149,"") | H40: =IF('1_참가선수입력'!$E$150<>"",'1_참가선수입력'!$E$150,"") | I40: =IF('1_참가선수입력'!$E$151<>"",'1_참가선수입력'!$E$151,"") | J40: =TEXTJOIN(" / ",TRUE,'1_참가선수입력'!C148:D151) -> #NAME?
...

Sheet 3_입금비용체크
A1: 참가비 및 참가자 부담 비용 체크표
A3: 번호 | B3: 이름 | C3: 참가구분 | D3: 성별 | E3: 참가비 50,000 | F3: 그린피 | G3: 카트비 | H3: 캐디피 | I3: 객실 | J3: 조식 | K3: 중식 | L3: 총입금상태 | M3: 입금메모 | N3: 비고
A4: ='1_참가선수입력'!A4 -> 1 | B4: ='1_참가선수입력'!E4 -> 0 | C4: ='1_참가선수입력'!C4 -> 0 | D4: ='1_참가선수입력'!D4 -> 0 | L4: =IF(AND(E4="완료",F4="완료",G4="완료",H4="완료"),"완료","확인필요") -> 확인필요
A5: ='1_참가선수입력'!A5 -> 2 | B5: ='1_참가선수입력'!E5 -> 0 | C5: ='1_참가선수입력'!C5 -> 0 | D5: ='1_참가선수입력'!D5 -> 0 | L5: =IF(AND(E5="완료",F5="완료",G5="완료",H5="완료"),"완료","확인필요") -> 확인필요
A6: ='1_참가선수입력'!A6 -> 3 | B6: ='1_참가선수입력'!E6 -> 0 | C6: ='1_참가선수입력'!C6 -> 0 | D6: ='1_참가선수입력'!D6 -> 0 | L6: =IF(AND(E6="완료",F6="완료",G6="완료",H6="완료"),"완료","확인필요") -> 확인필요
A7: ='1_참가선수입력'!A7 -> 4 | B7: ='1_참가선수입력'!E7 -> 0 | C7: ='1_참가선수입력'!C7 -> 0 | D7: ='1_참가선수입력'!D7 -> 0 | L7: =IF(AND(E7="완료",F7="완료",G7="완료",H7="완료"),"완료","확인필요") -> 확인필요
A8: ='1_참가선수입력'!A8 -> 5 | B8: ='1_참가선수입력'!E8 -> 0 | C8: ='1_참가선수입력'!C8 -> 0 | D8: ='1_참가선수입력'!D8 -> 0 | L8: =IF(AND(E8="완료",F8="완료",G8="완료",H8="완료"),"완료","확인필요") -> 확인필요
A9: ='1_참가선수입력'!A9 -> 6 | B9: ='1_참가선수입력'!E9 -> 0 | C9: ='1_참가선수입력'!C9 -> 0 | D9: ='1_참가선수입력'!D9 -> 0 | L9: =IF(AND(E9="완료",F9="완료",G9="완료",H9="완료"),"완료","확인필요") -> 확인필요
A10: ='1_참가선수입력'!A10 -> 7 | B10: ='1_참가선수입력'!E10 -> 0 | C10: ='1_참가선수입력'!C10 -> 0 | D10: ='1_참가선수입력'!D10 -> 0 | L10: =IF(AND(E10="완료",F10="완료",G10="완료",H10="완료"),"완료","확인필요") -> 확인필요
A11: ='1_참가선수입력'!A11 -> 8 | B11: ='1_참가선수입력'!E11 -> 0 | C11: ='1_참가선수입력'!C11 -> 0 | D11: ='1_참가선수입력'!D11 -> 0 | L11: =IF(AND(E11="완료",F11="완료",G11="완료",H11="완료"),"완료","확인필요") -> 확인필요
A12: ='1_참가선수입력'!A12 -> 9 | B12: ='1_참가선수입력'!E12 -> 0 | C12: ='1_참가선수입력'!C12 -> 0 | D12: ='1_참가선수입력'!D12 -> 0 | L12: =IF(AND(E12="완료",F12="완료",G12="완료",H12="완료"),"완료","확인필요") -> 확인필요
A13: ='1_참가선수입력'!A13 -> 10 | B13: ='1_참가선수입력'!E13 -> 0 | C13: ='1_참가선수입력'!C13 -> 0 | D13: ='1_참가선수입력'!D13 -> 0 | L13: =IF(AND(E13="완료",F13="완료",G13="완료",H13="완료"),"완료","확인필요") -> 확인필요
A14: ='1_참가선수입력'!A14 -> 11 | B14: ='1_참가선수입력'!E14 -> 0 | C14: ='1_참가선수입력'!C14 -> 0 | D14: ='1_참가선수입력'!D14 -> 0 | L14: =IF(AND(E14="완료",F14="완료",G14="완료",H14="완료"),"완료","확인필요") -> 확인필요
A15: ='1_참가선수입력'!A15 -> 12 | B15: ='1_참가선수입력'!E15 -> 0 | C15: ='1_참가선수입력'!C15 -> 0 | D15: ='1_참가선수입력'!D15 -> 0 | L15: =IF(AND(E15="완료",F15="완료",G15="완료",H15="완료"),"완료","확인필요") -> 확인필요
... A213: ='1_참가선수입력'!A213 -> 210 | B213: ='1_참가선수입력'!E213 -> 0 | C213: ='1_참가선수입력'!C213 -> 0 | D213: ='1_참가선수입력'!D213 -> 0 | L213: =IF(AND(E213="완료",F213="완료",G213="완료",H213="완료"),"완료","확인필요") -> 확인필요

Sheet 4_스코어입력
A1: 스코어 입력 및 최종일 진출 자동 산정
A3: 번호 | B3: 이름 | C3: 참가구분 | D3: 성별 | E3: 학교 | F3: 1R | G3: 카운트백/비고 | H3: 정렬키 | I3: 전체순위 | J3: 최종일 대상 | K3: 최종일순번 | L3: 2R | M3: 36홀 합계
A4: ='1_참가선수입력'!A4 -> 1 | B4: ='1_참가선수입력'!E4 -> 0 | C4: ='1_참가선수입력'!C4 -> 0 | D4: ='1_참가선수입력'!D4 -> 0 | E4: ='1_참가선수입력'!F4 -> 0 | H4: =IF(F4="","",F4+A4/10000) | I4: =IF(F4="","",RANK(H4,$H$4:$H$213,1)) | J4: =IF(I4="","",IF(I4<=104,"진출","")) | K4: =IF(J4="진출",I4,"") | M4: =IF(OR(F4="",L4=""),"",F4+L4)
A5: ='1_참가선수입력'!A5 -> 2 | B5: ='1_참가선수입력'!E5 -> 0 | C5: ='1_참가선수입력'!C5 -> 0 | D5: ='1_참가선수입력'!D5 -> 0 | E5: ='1_참가선수입력'!F5 -> 0 | H5: =IF(F5="","",F5+A5/10000) | I5: =IF(F5="","",RANK(H5,$H$4:$H$213,1)) | J5: =IF(I5="","",IF(I5<=104,"진출","")) | K5: =IF(J5="진출",I5,"") | M5: =IF(OR(F5="",L5=""),"",F5+L5)
A6: ='1_참가선수입력'!A6 -> 3 | B6: ='1_참가선수입력'!E6 -> 0 | C6: ='1_참가선수입력'!C6 -> 0 | D6: ='1_참가선수입력'!D6 -> 0 | E6: ='1_참가선수입력'!F6 -> 0 | H6: =IF(F6="","",F6+A6/10000) | I6: =IF(F6="","",RANK(H6,$H$4:$H$213,1)) | J6: =IF(I6="","",IF(I6<=104,"진출","")) | K6: =IF(J6="진출",I6,"") | M6: =IF(OR(F6="",L6=""),"",F6+L6)
A7: ='1_참가선수입력'!A7 -> 4 | B7: ='1_참가선수입력'!E7 -> 0 | C7: ='1_참가선수입력'!C7 -> 0 | D7: ='1_참가선수입력'!D7 -> 0 | E7: ='1_참가선수입력'!F7 -> 0 | H7: =IF(F7="","",F7+A7/10000) | I7: =IF(F7="","",RANK(H7,$H$4:$H$213,1)) | J7: =IF(I7="","",IF(I7<=104,"진출","")) | K7: =IF(J7="진출",I7,"") | M7: =IF(OR(F7="",L7=""),"",F7+L7)
A8: ='1_참가선수입력'!A8 -> 5 | B8: ='1_참가선수입력'!E8 -> 0 | C8: ='1_참가선수입력'!C8 -> 0 | D8: ='1_참가선수입력'!D8 -> 0 | E8: ='1_참가선수입력'!F8 -> 0 | H8: =IF(F8="","",F8+A8/10000) | I8: =IF(F8="","",RANK(H8,$H$4:$H$213,1)) | J8: =IF(I8="","",IF(I8<=104,"진출","")) | K8: =IF(J8="진출",I8,"") | M8: =IF(OR(F8="",L8=""),"",F8+L8)
A9: ='1_참가선수입력'!A9 -> 6 | B9: ='1_참가선수입력'!E9 -> 0 | C9: ='1_참가선수입력'!C9 -> 0 | D9: ='1_참가선수입력'!D9 -> 0 | E9: ='1_참가선수입력'!F9 -> 0 | H9: =IF(F9="","",F9+A9/10000) | I9: =IF(F9="","",RANK(H9,$H$4:$H$213,1)) | J9: =IF(I9="","",IF(I9<=104,"진출","")) | K9: =IF(J9="진출",I9,"") | M9: =IF(OR(F9="",L9=""),"",F9+L9)
A10: ='1_참가선수입력'!A10 -> 7 | B10: ='1_참가선수입력'!E10 -> 0 | C10: ='1_참가선수입력'!C10 -> 0 | D10: ='1_참가선수입력'!D10 -> 0 | E10: ='1_참가선수입력'!F10 -> 0 | H10: =IF(F10="","",F10+A10/10000) | I10: =IF(F10="","",RANK(H10,$H$4:$H$213,1)) | J10: =IF(I10="","",IF(I10<=104,"진출","")) | K10: =IF(J10="진출",I10,"") | M10: =IF(OR(F10="",L10=""),"",F10+L10)
A11: ='1_참가선수입력'!A11 -> 8 | B11: ='1_참가선수입력'!E11 -> 0 | C11: ='1_참가선수입력'!C11 -> 0 | D11: ='1_참가선수입력'!D11 -> 0 | E11: ='1_참가선수입력'!F11 -> 0 | H11: =IF(F11="","",F11+A11/10000) | I11: =IF(F11="","",RANK(H11,$H$4:$H$213,1)) | J11: =IF(I11="","",IF(I11<=104,"진출","")) | K11: =IF(J11="진출",I11,"") | M11: =IF(OR(F11="",L11=""),"",F11+L11)
A12: ='1_참가선수입력'!A12 -> 9 | B12: ='1_참가선수입력'!E12 -> 0 | C12: ='1_참가선수입력'!C12 -> 0 | D12: ='1_참가선수입력'!D12 -> 0 | E12: ='1_참가선수입력'!F12 -> 0 | H12: =IF(F12="","",F12+A12/10000) | I12: =IF(F12="","",RANK(H12,$H$4:$H$213,1)) | J12: =IF(I12="","",IF(I12<=104,"진출","")) | K12: =IF(J12="진출",I12,"") | M12: =IF(OR(F12="",L12=""),"",F12+L12)
A13: ='1_참가선수입력'!A13 -> 10 | B13: ='1_참가선수입력'!E13 -> 0 | C13: ='1_참가선수입력'!C13 -> 0 | D13: ='1_참가선수입력'!D13 -> 0 | E13: ='1_참가선수입력'!F13 -> 0 | H13: =IF(F13="","",F13+A13/10000) | I13: =IF(F13="","",RANK(H13,$H$4:$H$213,1)) | J13: =IF(I13="","",IF(I13<=104,"진출","")) | K13: =IF(J13="진출",I13,"") | M13: =IF(OR(F13="",L13=""),"",F13+L13)
A14: ='1_참가선수입력'!A14 -> 11 | B14: ='1_참가선수입력'!E14 -> 0 | C14: ='1_참가선수입력'!C14 -> 0 | D14: ='1_참가선수입력'!D14 -> 0 | E14: ='1_참가선수입력'!F14 -> 0 | H14: =IF(F14="","",F14+A14/10000) | I14: =IF(F14="","",RANK(H14,$H$4:$H$213,1)) | J14: =IF(I14="","",IF(I14<=104,"진출","")) | K14: =IF(J14="진출",I14,"") | M14: =IF(OR(F14="",L14=""),"",F14+L14)
A15: ='1_참가선수입력'!A15 -> 12 | B15: ='1_참가선수입력'!E15 -> 0 | C15: ='1_참가선수입력'!C15 -> 0 | D15: ='1_참가선수입력'!D15 -> 0 | E15: ='1_참가선수입력'!F15 -> 0 | H15: =IF(F15="","",F15+A15/10000) | I15: =IF(F15="","",RANK(H15,$H$4:$H$213,1)) | J15: =IF(I15="","",IF(I15<=104,"진출","")) | K15: =IF(J15="진출",I15,"") | M15: =IF(OR(F15="",L15=""),"",F15+L15)
... A213: ='1_참가선수입력'!A213 -> 210 | B213: ='1_참가선수입력'!E213 -> 0 | C213: ='1_참가선수입력'!C213 -> 0 | D213: ='1_참가선수입력'!D213 -> 0 | E213: ='1_참가선수입력'!F213 -> 0 | H213: =IF(F213="","",F213+A213/10000) | I213: =IF(F213="","",RANK(H213,$H$4:$H$213,1)) | J213: =IF(I213="","",IF(I213<=104,"진출","")) | K213: =IF(J213="진출",I213,"") | M213: =IF(OR(F213="",L213=""),"",F213+L213)

Sheet 5_최종일조편성
A1: 최종일 자동 조편성표 (1R 상위 104명 기준)
N2: 최종일 시작 | O2: 11:30
A3: 조 | B3: 일자 | C3: 라운드 | D3: 부 | E3: 출발시간 | F3: 선수1 | G3: 선수2 | H3: 선수3 | I3: 선수4 | J3: 1R 순위범위 | K3: 카트/캐디 | L3: 비고 | N3: 간격(분) | O3: 8 | Q3: 순번 | R3: 선수명 | S3: 1R | T3: 원번호
A4: 1 | B4: 6/25(목) | C4: 최종라운드 | D4: 2부 | E4: =$O$2+(A4-1)*TIME(0,$O$3,0) -> 0.47916667 | F4: =IF($R$4<>"",$R$4,"") | G4: =IF($R$5<>"",$R$5,"") | H4: =IF($R$6<>"",$R$6,"") | I4: =IF($R$7<>"",$R$7,"") | J4: 1~4위 | Q4: 1 | R4: =IFERROR(INDEX('4_스코어입력'!$B$4:$B$213,MATCH(Q4,'4_스코어입력'!$I$4:$I$213,0)),"") | S4: =IFERROR(INDEX('4_스코어입력'!$F$4:$F$213,MATCH(Q4,'4_스코어입력'!$I$4:$I$213,0)),"") | T4: =IFERROR(INDEX('4_스코어입력'!$A$4:$A$213,MATCH(Q4,'4_스코어입력'!$I$4:$I$213,0)),"")
A5: 2 | B5: 6/25(목) | C5: 최종라운드 | D5: 2부 | E5: =$O$2+(A5-1)*TIME(0,$O$3,0) -> 0.48472222 | F5: =IF($R$8<>"",$R$8,"") | G5: =IF($R$9<>"",$R$9,"") | H5: =IF($R$10<>"",$R$10,"") | I5: =IF($R$11<>"",$R$11,"") | J5: 5~8위 | Q5: 2 | R5: =IFERROR(INDEX('4_스코어입력'!$B$4:$B$213,MATCH(Q5,'4_스코어입력'!$I$4:$I$213,0)),"") | S5: =IFERROR(INDEX('4_스코어입력'!$F$4:$F$213,MATCH(Q5,'4_스코어입력'!$I$4:$I$213,0)),"") | T5: =IFERROR(INDEX('4_스코어입력'!$A$4:$A$213,MATCH(Q5,'4_스코어입력'!$I$4:$I$213,0)),"")
A6: 3 | B6: 6/25(목) | C6: 최종라운드 | D6: 2부 | E6: =$O$2+(A6-1)*TIME(0,$O$3,0) -> 0.49027778 | F6: =IF($R$12<>"",$R$12,"") | G6: =IF($R$13<>"",$R$13,"") | H6: =IF($R$14<>"",$R$14,"") | I6: =IF($R$15<>"",$R$15,"") | J6: 9~12위 | Q6: 3 | R6: =IFERROR(INDEX('4_스코어입력'!$B$4:$B$213,MATCH(Q6,'4_스코어입력'!$I$4:$I$213,0)),"") | S6: =IFERROR(INDEX('4_스코어입력'!$F$4:$F$213,MATCH(Q6,'4_스코어입력'!$I$4:$I$213,0)),"") | T6: =IFERROR(INDEX('4_스코어입력'!$A$4:$A$213,MATCH(Q6,'4_스코어입력'!$I$4:$I$213,0)),"")
A7: 4 | B7: 6/25(목) | C7: 최종라운드 | D7: 2부 | E7: =$O$2+(A7-1)*TIME(0,$O$3,0) -> 0.49583333 | F7: =IF($R$16<>"",$R$16,"") | G7: =IF($R$17<>"",$R$17,"") | H7: =IF($R$18<>"",$R$18,"") | I7: =IF($R$19<>"",$R$19,"") | J7: 13~16위 | Q7: 4 | R7: =IFERROR(INDEX('4_스코어입력'!$B$4:$B$213,MATCH(Q7,'4_스코어입력'!$I$4:$I$213,0)),"") | S7: =IFERROR(INDEX('4_스코어입력'!$F$4:$F$213,MATCH(Q7,'4_스코어입력'!$I$4:$I$213,0)),"") | T7: =IFERROR(INDEX('4_스코어입력'!$A$4:$A$213,MATCH(Q7,'4_스코어입력'!$I$4:$I$213,0)),"")
A8: 5 | B8: 6/25(목) | C8: 최종라운드 | D8: 2부 | E8: =$O$2+(A8-1)*TIME(0,$O$3,0) -> 0.50138889 | F8: =IF($R$20<>"",$R$20,"") | G8: =IF($R$21<>"",$R$21,"") | H8: =IF($R$22<>"",$R$22,"") | I8: =IF($R$23<>"",$R$23,"") | J8: 17~20위 | Q8: 5 | R8: =IFERROR(INDEX('4_스코어입력'!$B$4:$B$213,MATCH(Q8,'4_스코어입력'!$I$4:$I$213,0)),"") | S8: =IFERROR(INDEX('4_스코어입력'!$F$4:$F$213,MATCH(Q8,'4_스코어입력'!$I$4:$I$213,0)),"") | T8: =IFERROR(INDEX('4_스코어입력'!$A$4:$A$213,MATCH(Q8,'4_스코어입력'!$I$4:$I$213,0)),"")
A9: 6 | B9: 6/25(목) | C9: 최종라운드 | D9: 2부 | E9: =$O$2+(A9-1)*TIME(0,$O$3,0) -> 0.50694444 | F9: =IF($R$24<>"",$R$24,"") | G9: =IF($R$25<>"",$R$25,"") | H9: =IF($R$26<>"",$R$26,"") | I9: =IF($R$27<>"",$R$27,"") | J9: 21~24위 | Q9: 6 | R9: =IFERROR(INDEX('4_스코어입력'!$B$4:$B$213,MATCH(Q9,'4_스코어입력'!$I$4:$I$213,0)),"") | S9: =IFERROR(INDEX('4_스코어입력'!$F$4:$F$213,MATCH(Q9,'4_스코어입력'!$I$4:$I$213,0)),"") | T9: =IFERROR(INDEX('4_스코어입력'!$A$4:$A$213,MATCH(Q9,'4_스코어입력'!$I$4:$I$213,0)),"")
A10: 7 | B10: 6/25(목) | C10: 최종라운드 | D10: 2부 | E10: =$O$2+(A10-1)*TIME(0,$O$3,0) -> 0.5125 | F10: =IF($R$28<>"",$R$28,"") | G10: =IF($R$29<>"",$R$29,"") | H10: =IF($R$30<>"",$R$30,"") | I10: =IF($R$31<>"",$R$31,"") | J10: 25~28위 | Q10: 7 | R10: =IFERROR(INDEX('4_스코어입력'!$B$4:$B$213,MATCH(Q10,'4_스코어입력'!$I$4:$I$213,0)),"") | S10: =IFERROR(INDEX('4_스코어입력'!$F$4:$F$213,MATCH(Q10,'4_스코어입력'!$I$4:$I$213,0)),"") | T10: =IFERROR(INDEX('4_스코어입력'!$A$4:$A$213,MATCH(Q10,'4_스코어입력'!$I$4:$I$213,0)),"")
A11: 8 | B11: 6/25(목) | C11: 최종라운드 | D11: 2부 | E11: =$O$2+(A11-1)*TIME(0,$O$3,0) -> 0.51805556 | F11: =IF($R$32<>"",$R$32,"") | G11: =IF($R$33<>"",$R$33,"") | H11: =IF($R$34<>"",$R$34,"") | I11: =IF($R$35<>"",$R$35,"") | J11: 29~32위 | Q11: 8 | R11: =IFERROR(INDEX('4_스코어입력'!$B$4:$B$213,MATCH(Q11,'4_스코어입력'!$I$4:$I$213,0)),"") | S11: =IFERROR(INDEX('4_스코어입력'!$F$4:$F$213,MATCH(Q11,'4_스코어입력'!$I$4:$I$213,0)),"") | T11: =IFERROR(INDEX('4_스코어입력'!$A$4:$A$213,MATCH(Q11,'4_스코어입력'!$I$4:$I$213,0)),"")
A12: 9 | B12: 6/25(목) | C12: 최종라운드 | D12: 2부 | E12: =$O$2+(A12-1)*TIME(0,$O$3,0) -> 0.52361111 | F12: =IF($R$36<>"",$R$36,"") | G12: =IF($R$37<>"",$R$37,"") | H12: =IF($R$38<>"",$R$38,"") | I12: =IF($R$39<>"",$R$39,"") | J12: 33~36위 | Q12: 9 | R12: =IFERROR(INDEX('4_스코어입력'!$B$4:$B$213,MATCH(Q12,'4_스코어입력'!$I$4:$I$213,0)),"") | S12: =IFERROR(INDEX('4_스코어입력'!$F$4:$F$213,MATCH(Q12,'4_스코어입력'!$I$4:$I$213,0)),"") | T12: =IFERROR(INDEX('4_스코어입력'!$A$4:$A$213,MATCH(Q12,'4_스코어입력'!$I$4:$I$213,0)),"")
A13: 10 | B13: 6/25(목) | C13: 최종라운드 | D13: 2부 | E13: =$O$2+(A13-1)*TIME(0,$O$3,0) -> 0.52916667 | F13: =IF($R$40<>"",$R$40,"") | G13: =IF($R$41<>"",$R$41,"") | H13: =IF($R$42<>"",$R$42,"") | I13: =IF($R$43<>"",$R$43,"") | J13: 37~40위 | Q13: 10 | R13: =IFERROR(INDEX('4_스코어입력'!$B$4:$B$213,MATCH(Q13,'4_스코어입력'!$I$4:$I$213,0)),"") | S13: =IFERROR(INDEX('4_스코어입력'!$F$4:$F$213,MATCH(Q13,'4_스코어입력'!$I$4:$I$213,0)),"") | T13: =IFERROR(INDEX('4_스코어입력'!$A$4:$A$213,MATCH(Q13,'4_스코어입력'!$I$4:$I$213,0)),"")
A14: 11 | B14: 6/25(목) | C14: 최종라운드 | D14: 2부 | E14: =$O$2+(A14-1)*TIME(0,$O$3,0) -> 0.53472222 | F14: =IF($R$44<>"",$R$44,"") | G14: =IF($R$45<>"",$R$45,"") | H14: =IF($R$46<>"",$R$46,"") | I14: =IF($R$47<>"",$R$47,"") | J14: 41~44위 | Q14: 11 | R14: =IFERROR(INDEX('4_스코어입력'!$B$4:$B$213,MATCH(Q14,'4_스코어입력'!$I$4:$I$213,0)),"") | S14: =IFERROR(INDEX('4_스코어입력'!$F$4:$F$213,MATCH(Q14,'4_스코어입력'!$I$4:$I$213,0)),"") | T14: =IFERROR(INDEX('4_스코어입력'!$A$4:$A$213,MATCH(Q14,'4_스코어입력'!$I$4:$I$213,0)),"")
A15: 12 | B15: 6/25(목) | C15: 최종라운드 | D15: 2부 | E15: =$O$2+(A15-1)*TIME(0,$O$3,0) -> 0.54027778 | F15: =IF($R$48<>"",$R$48,"") | G15: =IF($R$49<>"",$R$49,"") | H15: =IF($R$50<>"",$R$50,"") | I15: =IF($R$51<>"",$R$51,"") | J15: 45~48위 | Q15: 12 | R15: =IFERROR(INDEX('4_스코어입력'!$B$4:$B$213,MATCH(Q15,'4_스코어입력'!$I$4:$I$213,0)),"") | S15: =IFERROR(INDEX('4_스코어입력'!$F$4:$F$213,MATCH(Q15,'4_스코어입력'!$I$4:$I$213,0)),"") | T15: =IFERROR(INDEX('4_스코어입력'!$A$4:$A$213,MATCH(Q15,'4_스코어입력'!$I$4:$I$213,0)),"")
A16: 13 | B16: 6/25(목) | C16: 최종라운드 | D16: 2부 | E16: =$O$2+(A16-1)*TIME(0,$O$3,0) -> 0.54583333 | F16: =IF($R$52<>"",$R$52,"") | G16: =IF($R$53<>"",$R$53,"") | H16: =IF($R$54<>"",$R$54,"") | I16: =IF($R$55<>"",$R$55,"") | J16: 49~52위 | Q16: 13 | R16: =IFERROR(INDEX('4_스코어입력'!$B$4:$B$213,MATCH(Q16,'4_스코어입력'!$I$4:$I$213,0)),"") | S16: =IFERROR(INDEX('4_스코어입력'!$F$4:$F$213,MATCH(Q16,'4_스코어입력'!$I$4:$I$213,0)),"") | T16: =IFERROR(INDEX('4_스코어입력'!$A$4:$A$213,MATCH(Q16,'4_스코어입력'!$I$4:$I$213,0)),"")
A17: 14 | B17: 6/25(목) | C17: 최종라운드 | D17: 2부 | E17: =$O$2+(A17-1)*TIME(0,$O$3,0) -> 0.55138889 | F17: =IF($R$56<>"",$R$56,"") | G17: =IF($R$57<>"",$R$57,"") | H17: =IF($R$58<>"",$R$58,"") | I17: =IF($R$59<>"",$R$59,"") | J17: 53~56위 | Q17: 14 | R17: =IFERROR(INDEX('4_스코어입력'!$B$4:$B$213,MATCH(Q17,'4_스코어입력'!$I$4:$I$213,0)),"") | S17: =IFERROR(INDEX('4_스코어입력'!$F$4:$F$213,MATCH(Q17,'4_스코어입력'!$I$4:$I$213,0)),"") | T17: =IFERROR(INDEX('4_스코어입력'!$A$4:$A$213,MATCH(Q17,'4_스코어입력'!$I$4:$I$213,0)),"")
A18: 15 | B18: 6/25(목) | C18: 최종라운드 | D18: 2부 | E18: =$O$2+(A18-1)*TIME(0,$O$3,0) -> 0.55694444 | F18: =IF($R$60<>"",$R$60,"") | G18: =IF($R$61<>"",$R$61,"") | H18: =IF($R$62<>"",$R$62,"") | I18: =IF($R$63<>"",$R$63,"") | J18: 57~60위 | Q18: 15 | R18: =IFERROR(INDEX('4_스코어입력'!$B$4:$B$213,MATCH(Q18,'4_스코어입력'!$I$4:$I$213,0)),"") | S18: =IFERROR(INDEX('4_스코어입력'!$F$4:$F$213,MATCH(Q18,'4_스코어입력'!$I$4:$I$213,0)),"") | T18: =IFERROR(INDEX('4_스코어입력'!$A$4:$A$213,MATCH(Q18,'4_스코어입력'!$I$4:$I$213,0)),"")
A19: 16 | B19: 6/25(목) | C19: 최종라운드 | D19: 2부 | E19: =$O$2+(A19-1)*TIME(0,$O$3,0) -> 0.5625 | F19: =IF($R$64<>"",$R$64,"") | G19: =IF($R$65<>"",$R$65,"") | H19: =IF($R$66<>"",$R$66,"") | I19: =IF($R$67<>"",$R$67,"") | J19: 61~64위 | Q19: 16 | R19: =IFERROR(INDEX('4_스코어입력'!$B$4:$B$213,MATCH(Q19,'4_스코어입력'!$I$4:$I$213,0)),"") | S19: =IFERROR(INDEX('4_스코어입력'!$F$4:$F$213,MATCH(Q19,'4_스코어입력'!$I$4:$I$213,0)),"") | T19: =IFERROR(INDEX('4_스코어입력'!$A$4:$A$213,MATCH(Q19,'4_스코어입력'!$I$4:$I$213,0)),"")
A20: 17 | B20: 6/25(목) | C20: 최종라운드 | D20: 2부 | E20: =$O$2+(A20-1)*TIME(0,$O$3,0) -> 0.56805556 | F20: =IF($R$68<>"",$R$68,"") | G20: =IF($R$69<>"",$R$69,"") | H20: =IF($R$70<>"",$R$70,"") | I20: =IF($R$71<>"",$R$71,"") | J20: 65~68위 | Q20: 17 | R20: =IFERROR(INDEX('4_스코어입력'!$B$4:$B$213,MATCH(Q20,'4_스코어입력'!$I$4:$I$213,0)),"") | S20: =IFERROR(INDEX('4_스코어입력'!$F$4:$F$213,MATCH(Q20,'4_스코어입력'!$I$4:$I$213,0)),"") | T20: =IFERROR(INDEX('4_스코어입력'!$A$4:$A$213,MATCH(Q20,'4_스코어입력'!$I$4:$I$213,0)),"")
A21: 18 | B21: 6/25(목) | C21: 최종라운드 | D21: 2부 | E21: =$O$2+(A21-1)*TIME(0,$O$3,0) -> 0.57361111 | F21: =IF($R$72<>"",$R$72,"") | G21: =IF($R$73<>"",$R$73,"") | H21: =IF($R$74<>"",$R$74,"") | I21: =IF($R$75<>"",$R$75,"") | J21: 69~72위 | Q21: 18 | R21: =IFERROR(INDEX('4_스코어입력'!$B$4:$B$213,MATCH(Q21,'4_스코어입력'!$I$4:$I$213,0)),"") | S21: =IFERROR(INDEX('4_스코어입력'!$F$4:$F$213,MATCH(Q21,'4_스코어입력'!$I$4:$I$213,0)),"") | T21: =IFERROR(INDEX('4_스코어입력'!$A$4:$A$213,MATCH(Q21,'4_스코어입력'!$I$4:$I$213,0)),"")
A22: 19 | B22: 6/25(목) | C22: 최종라운드 | D22: 2부 | E22: =$O$2+(A22-1)*TIME(0,$O$3,0) -> 0.57916667 | F22: =IF($R$76<>"",$R$76,"") | G22: =IF($R$77<>"",$R$77,"") | H22: =IF($R$78<>"",$R$78,"") | I22: =IF($R$79<>"",$R$79,"") | J22: 73~76위 | Q22: 19 | R22: =IFERROR(INDEX('4_스코어입력'!$B$4:$B$213,MATCH(Q22,'4_스코어입력'!$I$4:$I$213,0)),"") | S22: =IFERROR(INDEX('4_스코어입력'!$F$4:$F$213,MATCH(Q22,'4_스코어입력'!$I$4:$I$213,0)),"") | T22: =IFERROR(INDEX('4_스코어입력'!$A$4:$A$213,MATCH(Q22,'4_스코어입력'!$I$4:$I$213,0)),"")
A23: 20 | B23: 6/25(목) | C23: 최종라운드 | D23: 2부 | E23: =$O$2+(A23-1)*TIME(0,$O$3,0) -> 0.58472222 | F23: =IF($R$80<>"",$R$80,"") | G23: =IF($R$81<>"",$R$81,"") | H23: =IF($R$82<>"",$R$82,"") | I23: =IF($R$83<>"",$R$83,"") | J23: 77~80위 | Q23: 20 | R23: =IFERROR(INDEX('4_스코어입력'!$B$4:$B$213,MATCH(Q23,'4_스코어입력'!$I$4:$I$213,0)),"") | S23: =IFERROR(INDEX('4_스코어입력'!$F$4:$F$213,MATCH(Q23,'4_스코어입력'!$I$4:$I$213,0)),"") | T23: =IFERROR(INDEX('4_스코어입력'!$A$4:$A$213,MATCH(Q23,'4_스코어입력'!$I$4:$I$213,0)),"")
A24: 21 | B24: 6/25(목) | C24: 최종라운드 | D24: 2부 | E24: =$O$2+(A24-1)*TIME(0,$O$3,0) -> 0.59027778 | F24: =IF($R$84<>"",$R$84,"") | G24: =IF($R$85<>"",$R$85,"") | H24: =IF($R$86<>"",$R$86,"") | I24: =IF($R$87<>"",$R$87,"") | J24: 81~84위 | Q24: 21 | R24: =IFERROR(INDEX('4_스코어입력'!$B$4:$B$213,MATCH(Q24,'4_스코어입력'!$I$4:$I$213,0)),"") | S24: =IFERROR(INDEX('4_스코어입력'!$F$4:$F$213,MATCH(Q24,'4_스코어입력'!$I$4:$I$213,0)),"") | T24: =IFERROR(INDEX('4_스코어입력'!$A$4:$A$213,MATCH(Q24,'4_스코어입력'!$I$4:$I$213,0)),"")
A25: 22 | B25: 6/25(목) | C25: 최종라운드 | D25: 2부 | E25: =$O$2+(A25-1)*TIME(0,$O$3,0) -> 0.59583333 | F25: =IF($R$88<>"",$R$88,"") | G25: =IF($R$89<>"",$R$89,"") | H25: =IF($R$90<>"",$R$90,"") | I25: =IF($R$91<>"",$R$91,"") | J25: 85~88위 | Q25: 22 | R25: =IFERROR(INDEX('4_스코어입력'!$B$4:$B$213,MATCH(Q25,'4_스코어입력'!$I$4:$I$213,0)),"") | S25: =IFERROR(INDEX('4_스코어입력'!$F$4:$F$213,MATCH(Q25,'4_스코어입력'!$I$4:$I$213,0)),"") | T25: =IFERROR(INDEX('4_스코어입력'!$A$4:$A$213,MATCH(Q25,'4_스코어입력'!$I$4:$I$213,0)),"")
A26: 23 | B26: 6/25(목) | C26: 최종라운드 | D26: 2부 | E26: =$O$2+(A26-1)*TIME(0,$O$3,0) -> 0.60138889 | F26: =IF($R$92<>"",$R$92,"") | G26: =IF($R$93<>"",$R$93,"") | H26: =IF($R$94<>"",$R$94,"") | I26: =IF($R$95<>"",$R$95,"") | J26: 89~92위 | Q26: 23 | R26: =IFERROR(INDEX('4_스코어입력'!$B$4:$B$213,MATCH(Q26,'4_스코어입력'!$I$4:$I$213,0)),"") | S26: =IFERROR(INDEX('4_스코어입력'!$F$4:$F$213,MATCH(Q26,'4_스코어입력'!$I$4:$I$213,0)),"") | T26: =IFERROR(INDEX('4_스코어입력'!$A$4:$A$213,MATCH(Q26,'4_스코어입력'!$I$4:$I$213,0)),"")
A27: 24 | B27: 6/25(목) | C27: 최종라운드 | D27: 2부 | E27: =$O$2+(A27-1)*TIME(0,$O$3,0) -> 0.60694444 | F27: =IF($R$96<>"",$R$96,"") | G27: =IF($R$97<>"",$R$97,"") | H27: =IF($R$98<>"",$R$98,"") | I27: =IF($R$99<>"",$R$99,"") | J27: 93~96위 | Q27: 24 | R27: =IFERROR(INDEX('4_스코어입력'!$B$4:$B$213,MATCH(Q27,'4_스코어입력'!$I$4:$I$213,0)),"") | S27: =IFERROR(INDEX('4_스코어입력'!$F$4:$F$213,MATCH(Q27,'4_스코어입력'!$I$4:$I$213,0)),"") | T27: =IFERROR(INDEX('4_스코어입력'!$A$4:$A$213,MATCH(Q27,'4_스코어입력'!$I$4:$I$213,0)),"")
A28: 25 | B28: 6/25(목) | C28: 최종라운드 | D28: 2부 | E28: =$O$2+(A28-1)*TIME(0,$O$3,0) -> 0.6125 | F28: =IF($R$100<>"",$R$100,"") | G28: =IF($R$101<>"",$R$101,"") | H28: =IF($R$102<>"",$R$102,"") | I28: =IF($R$103<>"",$R$103,"") | J28: 97~100위 | Q28: 25 | R28: =IFERROR(INDEX('4_스코어입력'!$B$4:$B$213,MATCH(Q28,'4_스코어입력'!$I$4:$I$213,0)),"") | S28: =IFERROR(INDEX('4_스코어입력'!$F$4:$F$213,MATCH(Q28,'4_스코어입력'!$I$4:$I$213,0)),"") | T28: =IFERROR(INDEX('4_스코어입력'!$A$4:$A$213,MATCH(Q28,'4_스코어입력'!$I$4:$I$213,0)),"")
A29: 26 | B29: 6/25(목) | C29: 최종라운드 | D29: 2부 | E29: =$O$2+(A29-1)*TIME(0,$O$3,0) -> 0.61805556 | F29: =IF($R$104<>"",$R$104,"") | G29: =IF($R$105<>"",$R$105,"") | H29: =IF($R$106<>"",$R$106,"") | I29: =IF($R$107<>"",$R$107,"") | J29: 101~104위 | Q29: 26 | R29: =IFERROR(INDEX('4_스코어입력'!$B$4:$B$213,MATCH(Q29,'4_스코어입력'!$I$4:$I$213,0)),"") | S29: =IFERROR(INDEX('4_스코어입력'!$F$4:$F$213,MATCH(Q29,'4_스코어입력'!$I$4:$I$213,0)),"") | T29: =IFERROR(INDEX('4_스코어입력'!$A$4:$A$213,MATCH(Q29,'4_스코어입력'!$I$4:$I$213,0)),"")
Q30: 27 | R30: =IFERROR(INDEX('4_스코어입력'!$B$4:$B$213,MATCH(Q30,'4_스코어입력'!$I$4:$I$213,0)),"") | S30: =IFERROR(INDEX('4_스코어입력'!$F$4:$F$213,MATCH(Q30,'4_스코어입력'!$I$4:$I$213,0)),"") | T30: =IFERROR(INDEX('4_스코어입력'!$A$4:$A$213,MATCH(Q30,'4_스코어입력'!$I$4:$I$213,0)),"")
Q31: 28 | R31: =IFERROR(INDEX('4_스코어입력'!$B$4:$B$213,MATCH(Q31,'4_스코어입력'!$I$4:$I$213,0)),"") | S31: =IFERROR(INDEX('4_스코어입력'!$F$4:$F$213,MATCH(Q31,'4_스코어입력'!$I$4:$I$213,0)),"") | T31: =IFERROR(INDEX('4_스코어입력'!$A$4:$A$213,MATCH(Q31,'4_스코어입력'!$I$4:$I$213,0)),"")
Q32: 29 | R32: =IFERROR(INDEX('4_스코어입력'!$B$4:$B$213,MATCH(Q32,'4_스코어입력'!$I$4:$I$213,0)),"") | S32: =IFERROR(INDEX('4_스코어입력'!$F$4:$F$213,MATCH(Q32,'4_스코어입력'!$I$4:$I$213,0)),"") | T32: =IFERROR(INDEX('4_스코어입력'!$A$4:$A$213,MATCH(Q32,'4_스코어입력'!$I$4:$I$213,0)),"")
Q33: 30 | R33: =IFERROR(INDEX('4_스코어입력'!$B$4:$B$213,MATCH(Q33,'4_스코어입력'!$I$4:$I$213,0)),"") | S33: =IFERROR(INDEX('4_스코어입력'!$F$4:$F$213,MATCH(Q33,'4_스코어입력'!$I$4:$I$213,0)),"") | T33: =IFERROR(INDEX('4_스코어입력'!$A$4:$A$213,MATCH(Q33,'4_스코어입력'!$I$4:$I$213,0)),"")
Q34: 31 | R34: =IFERROR(INDEX('4_스코어입력'!$B$4:$B$213,MATCH(Q34,'4_스코어입력'!$I$4:$I$213,0)),"") | S34: =IFERROR(INDEX('4_스코어입력'!$F$4:$F$213,MATCH(Q34,'4_스코어입력'!$I$4:$I$213,0)),"") | T34: =IFERROR(INDEX('4_스코어입력'!$A$4:$A$213,MATCH(Q34,'4_스코어입력'!$I$4:$I$213,0)),"")
Q35: 32 | R35: =IFERROR(INDEX('4_스코어입력'!$B$4:$B$213,MATCH(Q35,'4_스코어입력'!$I$4:$I$213,0)),"") | S35: =IFERROR(INDEX('4_스코어입력'!$F$4:$F$213,MATCH(Q35,'4_스코어입력'!$I$4:$I$213,0)),"") | T35: =IFERROR(INDEX('4_스코어입력'!$A$4:$A$213,MATCH(Q35,'4_스코어입력'!$I$4:$I$213,0)),"")
Q36: 33 | R36: =IFERROR(INDEX('4_스코어입력'!$B$4:$B$213,MATCH(Q36,'4_스코어입력'!$I$4:$I$213,0)),"") | S36: =IFERROR(INDEX('4_스코어입력'!$F$4:$F$213,MATCH(Q36,'4_스코어입력'!$I$4:$I$213,0)),"") | T36: =IFERROR(INDEX('4_스코어입력'!$A$4:$A$213,MATCH(Q36,'4_스코어입력'!$I$4:$I$213,0)),"")
Q37: 34 | R37: =IFERROR(INDEX('4_스코어입력'!$B$4:$B$213,MATCH(Q37,'4_스코어입력'!$I$4:$I$213,0)),"") | S37: =IFERROR(INDEX('4_스코어입력'!$F$4:$F$213,MATCH(Q37,'4_스코어입력'!$I$4:$I$213,0)),"") | T37: =IFERROR(INDEX('4_스코어입력'!$A$4:$A$213,MATCH(Q37,'4_스코어입력'!$I$4:$I$213,0)),"")
Q38: 35 | R38: =IFERROR(INDEX('4_스코어입력'!$B$4:$B$213,MATCH(Q38,'4_스코어입력'!$I$4:$I$213,0)),"") | S38: =IFERROR(INDEX('4_스코어입력'!$F$4:$F$213,MATCH(Q38,'4_스코어입력'!$I$4:$I$213,0)),"") | T38: =IFERROR(INDEX('4_스코어입력'!$A$4:$A$213,MATCH(Q38,'4_스코어입력'!$I$4:$I$213,0)),"")
Q39: 36 | R39: =IFERROR(INDEX('4_스코어입력'!$B$4:$B$213,MATCH(Q39,'4_스코어입력'!$I$4:$I$213,0)),"") | S39: =IFERROR(INDEX('4_스코어입력'!$F$4:$F$213,MATCH(Q39,'4_스코어입력'!$I$4:$I$213,0)),"") | T39: =IFERROR(INDEX('4_스코어입력'!$A$4:$A$213,MATCH(Q39,'4_스코어입력'!$I$4:$I$213,0)),"")
Q40: 37 | R40: =IFERROR(INDEX('4_스코어입력'!$B$4:$B$213,MATCH(Q40,'4_스코어입력'!$I$4:$I$213,0)),"") | S40: =IFERROR(INDEX('4_스코어입력'!$F$4:$F$213,MATCH(Q40,'4_스코어입력'!$I$4:$I$213,0)),"") | T40: =IFERROR(INDEX('4_스코어입력'!$A$4:$A$213,MATCH(Q40,'4_스코어입력'!$I$4:$I$213,0)),"")
...

Sheet 6_운영요약
A1: 운영 현황 자동 요약
A3: 항목 | B3: 값 | C3: 기준 | D3: 메모
A4: 총 등록 선수 | B4: =COUNTA('1_참가선수입력'!E4:E213) -> 0 | C4: 이름 입력 기준 | D4: 최대 210명
A5: 남자 선수 | B5: =COUNTIF('1_참가선수입력'!D4:D213,"남") -> 0 | C5: 성별 기준
A6: 여자 선수 | B6: =COUNTIF('1_참가선수입력'!D4:D213,"여") -> 0 | C6: 성별 기준
A7: 중학생 | B7: =COUNTIF('1_참가선수입력'!C4:C213,"중학생") -> 0 | C7: 참가구분 기준
A8: 고등학생 | B8: =COUNTIF('1_참가선수입력'!C4:C213,"고등학생") -> 0 | C8: 참가구분 기준
A9: 참가비 입금 완료 | B9: =COUNTIF('1_참가선수입력'!L4:L213,"완료") -> 0 | C9: 입금 완료 기준
A10: 서류 전체 완료 | B10: =COUNTIF('1_참가선수입력'!R4:R213,"완료") -> 0 | C10: 서류상태 기준
A11: 서류 확인 필요 | B11: =COUNTIF('1_참가선수입력'!R4:R213,"확인필요") -> 210 | C11: 서류상태 기준
A12: 최종일 진출자 | B12: =COUNTIF('4_스코어입력'!J4:J213,"진출") -> 0 | C12: 1R 상위 104명
A13: 남은 여유 인원 | B13: =210-COUNTA('1_참가선수입력'!E4:E213) -> 210 | C13: 최대 210명 기준

Sheet 7_사용안내
A1: 자동화 엑셀 사용 안내
A3: 순서 | B3: 해야 할 일 | C3: 사용 시트 | D3: 비고
A4: 1 | B4: 참가선수 정보를 입력합니다. | C4: 1_참가선수입력 | D4: 참가구분/성별/입금/서류는 드롭다운 선택
A5: 2 | B5: 1일차 조편성은 자동 생성됩니다. | C5: 2_1일차조편성 | D5: 입력 순서 기준 4명씩 1조
A6: 3 | B6: 참가비 및 비용 체크는 별도 관리합니다. | C6: 3_입금비용체크 | D6: 참가자 부담 비용 확인용
A7: 4 | B7: 1라운드 스코어를 입력합니다. | C7: 4_스코어입력 | D7: 1R 칸에 숫자 입력
A8: 5 | B8: 최종일 진출자와 조편성이 자동 생성됩니다. | C8: 5_최종일조편성 | D8: 1R 상위 104명 기준
A9: 6 | B9: 전체 현황은 자동 집계됩니다. | C9: 6_운영요약 | D9: 등록/입금/서류/진출자 현황 확인
